Workbook
Name ColumnTitle1: #REF!
Name ColumnTitleRegion1..B11.1: #REF!
Name Company_Name: #REF!
Name Profit_table: #REF!
Name RowTitleRegion1..D5: #REF!

Sheet Insutrcution for whole process
A1: check box | B1: Instruction for whole process
A2: FALSE | B2: 0. save as a new file
A3: FALSE | B3: 1. check detail for strata rep contacts, update if necessary
A4: FALSE | B4: 2. check detail for strata roll contacts, update if neccssary
A5: FALSE | B5: 3. update Amanda Energy bills using python code | C5: get invoice pdf from amanda energy | D5: get_Amanda_inovice.py | E5: output.csv
A6: FALSE | B6: 4. update auto meter reading (SwitchDin) | C6: download data from billing dashboard | D6: process_meter_data.py | E6: formatted data
A7: FALSE | B7: 5. update manual meter reading | C7: request manual meter reading ahead of time | D7: January 1st | E7: April 1st | F7: July 1st | G7: October 1st
A8: FALSE | B8: 6. check Tariff Rates, update if necessary
A9: FALSE | B9: 7. update master billing sheet to current billing cycle: | C9: cluster name and billing month
A10: FALSE | B10: 8. check supply table as follow, remove supply charge as request.
A11: FALSE | B11: 9. run VB code
A12: FALSE | B12: 10. Hide sensitve info sheet
B14: Instruction for VB code:
A15: FALSE | B15: 1. open tab 'Developer'
A16: FALSE | B16: 2. choose 'Visual Basic'
A17: FALSE | B17: 3. add module
A18: FALSE | B18: 4. copy and paste VB code | F18: Sub GenerateDynamicLotSheets() Dim wsTemplate As Worksheet Dim newSheet As Worksheet Dim strataRoll As Worksheet Dim clusterValue As String Dim maxLotNo As Long Dim rng As Range Dim cell As Range Dim i As Long ' Define the template sheet and reference sheet Set wsTemplate = ThisWorkbook.Sheets("Lot 1") Set strataRoll = ThisWorkbook.Sheets("Strata Roll") ' Get the Cluster value from D7 of the template sheet clusterValue = wsTemplate.Range("E7").Value ' Initialize the maximum Lot No maxLotNo = 0 ' Search "Strata Roll" for the maximum Lot No matching the Cluster value With strataRoll Set rng = .Range("A2", .Cells(.Rows.Count, "A").End(xlUp)) ' Assume data starts from A2 For Each cell In rng ' Check if the corresponding row's Cluster matches the target Cluster If .Cells(cell.Row, "B").Value = clusterValue Then ' Ensure the cell value in column A is numeric before comparing If IsNumeric(cell.Value) Then ' Compare the numeric Lot No directly If CLng(cell.Value) > maxLotNo Then maxLotNo = CLng(cell.Value) End If End If End If Next cell End With ' Check if any Lot No was found for the given Cluster If maxLotNo = 0 Then MsgBox "No Lot No found for Cluster value " & clusterValue & "!", vbExclamation Exit Sub End If ' Generate worksheets for Lot 2 to maxLotNo For i = 2 To maxLotNo ' Copy the template sheet wsTemplate.Copy After:=ThisWorkbook.Sheets(ThisWorkbook.Sheets.Count) Set newSheet = ThisWorkbook.Sheets(ThisWorkbook.Sheets.Count) ' Rename the new sheet newSheet.Name = "Lot " & i ' Update the Lot No in the new sheet (e.g., D8 cell) newSheet.Range("E8").Value = i Next i MsgBox "Successfully created Lot 2 to Lot " & maxLotNo & " worksheets!", vbInformation End Sub
A19: FALSE | B19: 5. run
A20: FALSE | B20: 6. remove VB code
B22: Invoicing table
B23: Cluster | C23: Account setup fee | D23: Q1 | E23: Q2 | F23: Q3 | G23: Q4 | H23: Jan-Feb | I23: Mar | J23: Redundant Invoices | K23: Contract Update
B24: 1A | C24: 1018 | D24: self- issued | E24: self- issued | F24: self- issued | G24: 1077 | H24: 1091 | J24: 1039 for Q1-Q3 | K24: Signed
B25: 1B | C25: 1019 | D25: self- issued | E25: self- issued | F25: self- issued | G25: 1069 | H25: 1092 | J25: 1043 for Q1-Q3 | K25: Weekend | M25: paid
B26: 1C | C26: 1020 | D26: 1044 | E26: 1044 | F26: 1044 | G26: 1070 | H26: 1093 | K26: Signed | M26: not paid
B27: 2A | C27: 1021 | D27: self- issued | E27: self- issued | F27: self- issued | G27: 1071 | J27: 1045 for Q2-Q3 | K27: Holiday | M27: Credit Note allocated
B28: 2B | C28: 1022 | D28: self- issued | E28: 1046 | F28: 1046 | G28: 1082 | H28: 1094 | K28: Weekend | M28: self- issued
B29: 3A | C29: 1023 | D29: self- issued | E29: 1047 | F29: 1047 | G29: 1081 | K29: Weekend
B30: 3B | C30: 1024 | D30: self- issued | E30: 1083 | F30: 1083 | G30: 1083 | H30: 1095 | J30: 1048 for Q2-Q3 | K30: FIFO working
B32: Supply charge table
B33: Cluster | C33: Amanda energy supply charge | D33: SwitchDin | E33: ChargeFox | F33: EV charger cost of electricy @P2P rate | G33: P2P trade rate for lots with export | H33: P2P rate for lots with no export | I33: Agreement and action items | J33: BESS status | K33: billing cycle | L33: P2P borrow/lend
B34: 1A | C34: Included | D34: Not included | E34: Not included | F34: Included | G34: 0.22$/kwh | H34: 0.36$/kwh | I34: July 1st 2025 | J34: ON | K34: quarterly | L34: 2
B35: 1B | C35: Included | D35: Not included Till May 2025 | E35: Not included | F35: Included | G35: 0.22$/kwh | H35: 0.22$/kwh | I35: July 1st 2025 | J35: ON | K35: quarterly | L35: 2
B36: 1C | C36: Included | D36: Included | E36: Included | F36: Included | G36: 0.22$/kwh | H36: 0.22$/kwh | J36: ON | K36: quarterly | L36: 2
B37: 2A | C37: Included | D37: Not included | E37: Not included | G37: 0.22$/kwh | H37: 0.22$/kwh | I37: July 1st 2025 | J37: ON | K37: quarterly | L37: 2
B38: 2B | C38: Included | D38: Included | E38: Not included | G38: 0.22$/kwh | H38: 0.22$/kwh | I38: July 1st 2025 | J38: ON | K38: quarterly | L38: 2
B39: 3A | C39: Not included | D39: Not included | E39: Not included | G39: 0.22$/kwh | H39: 0.22$/kwh | I39: July 1st 2025 | J39: ON | K39: quarterly | L39: 0
B40: 3B | C40: Not included | D40: Not included | E40: Not included | G40: 0.22$/kwh | H40: 0.22$/kwh | I40: July 1st 2025 | J40: ON | K40: quarterly | L40: 0
B41: FALSE | C41: FALSE | D41: FALSE | E41: FALSE | F41: FALSE | G41: FALSE | H41: FALSE | I41: FALSE | J41: FALSE | K41: FALSE | L41: FALSE

Sheet strata rep contacts
A1: Cluster | B1: Strata company name | C1: ABN | D1: Parcel Address | E1: Energy Representative | F1: Energy Representative email | G1: Strata Council Chair | H1: Strata Council Email | I1: Energy supply charge incl in strata fees | J1: Cluster battery | K1: Invividual lot battery | L1: number of lots | M1: Account Name | N1: BSB | O1: Account #
A2: 1A | B2: The Owners of Cluster 1A Witchcliffe Ecovillage Survey Strata 77784 | C2: ABN: 29 857 461 927 | D2: Lot 10, 10347 Bussell Hwy Witchcliffe WA | E2: Peter Froehlich (lot 13) | F2: froehlich.fp@gmail.com | G2: to be confirmed by strata | H2: wevcluster1a@gmail.com | J2: ✓ | M2: Owners Cluster 1A | N2: 633-000 | O2: 209 071 927
B3: 24 Lots | E3: Lindy Dunlop | F3: lindyjdunlop@hotmail.com | L3: 24
A4: 1B | B4: The Owners of Cluster 1B Witchcliffe Ecovillage Survey Strata 77785 | C4: ABN: 31 962 028 201 | D4: Lot 17, 10347 Bussell Hwy Witchcliffe WA | E4: Paul Wilkinson (lot 12) | F4: mail2paul07@gmail.com | G4: to be confirmed by strata | H4: wevcluster1b@gmail.com | J4: ✓ | M4: 1B Admin Fund | N4: 633000 | O4: 208 200 014
B5: 21 Lots | L5: 21
A6: 1C | B6: The Owners of Cluster 1C Witchcliffe Ecovillage Survey Strata 77786 | C6: ABN: 80 608 251 481 | D6: Lot 11, 10347 Bussell Hwy Witchcliffe WA | E6: Laurence Hansen (Lot 19) | F6: logs1@iinet.net.au | G6: to be confirmed by strata | H6: wevcluster1c@gmail.com | J6: ✓ | M6: WEV Cluster 1C Strata Account | N6: 633 000 | O6: 216 423 913
B7: 19 Lots | L7: 19
A9: 2A | B9: The Owners of Cluster 2A Witchcliffe Ecovillage Survey Strata 77787 | C9: ABN: 38 248 842 277 | D9: Lot 7 10347 Bussell Hwy Witchcliffe WA | E9: Bouwe Hamersma (Lot 5) | F9: bouwe.hamersma@gmail.com | G9: to be confirmed by strata | H9: wevcluster2a@gmail.com | J9: ✓ | M9: 2A ADMIN FUND | N9: 306-188 | O9: 352588
B10: 23 Lots | L10: 23
A11: 2B | B11: The Owners of Cluster 2B Witchcliffe Ecovillage Survey Strata 77788 | C11: ABN: 64 989 501 940 | D11: Lot 8, 10347 Bussell Hwy Witchcliffe WA | E11: Alison Askew (Lot 10) | F11: alisonaskew123@gmail.com | G11: to be confirmed by strata | H11: wevcluster2b@gmail.com | J11: ✓ | M11: The Owners of Cluster 2B Witchcliffe | N11: 633000 | O11: 209 181 437
B12: 22 Lots | L12: 22
A14: 3A | B14: The Owners of Cluster 3A Witchcliffe Ecovillage Survey Strata 77790 | C14: ABN: 22315195710 | D14: 2 Karrack Crescent, Witchcliffe WA | E14: Elaine Clocherty (Lot 15) | F14: elaineclocherty@gmail.com | G14: to be confirmed by strata | H14: wevcluster3a@gmail.com | I14: ✓ | J14: ✓ | M14: WEV Cluster 3A Strata | N14: 633 000 | O14: 223 075 870
B15: 27 Lots | L15: 27
A16: 3B | B16: The Owners of Cluster 3B Witchcliffe Ecovillage Survey Strata 77791 | C16: ABN: 11801467982 | D16: 3 Karrack Crescent, Witchcliffe WA | E16: Jason McHattan (Lot13) | F16: jasonmchattan@gmail.com | G16: to be confirmed by strata | H16: wevcluster3b@gmail.com | I16: ✓ | J16: ✓ | M16: 3B Admin Fund | N16: 306-412 | O16: 0020794
B17: 19 Lots | E17: Tim Thomson (Lot 8) | F17: timjcthomson@gmail.com | L17: 19
B18: The Owners of Cluster 3C Witchcliffe Ecovillage Survey Strata 83347 | C18: ABN: 86675221914 | D18: Lot 18 Karrack Crescent Witchcliffe WA | E18: ?? | G18: to be confirmed by strata | H18: wevcluster3c@gmail.com | I18: ✓ | K18: ✓
B19: 15 Short Stay | L19: 15
B21: The Owners of Cluster 4A Witchcliffe Ecovillage Survey Strata 85752 | C21: ABN: 33 677 155 303 | D21: 22 Gnuraren Grove, Witchcliffe WA | E21: ?? | G21: Caroline Bannister (Lot18) | H21: wevcluster4a@gmail.com | I21: ✓ | K21: ✓
B22: 26 lots | L22: 26
B23: The Owners of Cluster 4B Witchcliffe Ecovillage Survey Strata 85753 | C23: ABN: 24 266 141 390 | D23: 23 Mulal Avenue, Witchcliffe WA | E23: Manuel Mall (Lot 3) | F23: carolinandmanuel@gmail.com | G23: Jenny Challen (Lot 9) | H23: wevcluster4b@gmail.com | I23: ✓ | K23: ✓
B24: 20 lots | E24: Jenny Challen (Lot 9) | F24: jenny@challen.com.au | L24: 20

Sheet strata roll
A1: Lot | B1: cluster | C1: Meter# | D1: Block Type | E1: Owner | F1: Street Address | G1: Suburb | H1: State | I1: Post Code | J1: Unit Entitlement | K1: UE % over Cluster | L1: Calculated Battery Allocation (kWh) | M1: Inverter Model | N1: Applied Battery Allocation (kWh) | O1: Export Capacity (kW) | P1: Energy Meter Installed | Q1: PV Installed | R1: Functional Droplet | S1: Stage of Dev. | T1: Phone 1 | U1: Phone 2 | V1: Email | W1: Meter Number | X1: Occupant 1 Start Date | Y1: Occupant 1 End date | Z1: Inverter start date
A2: 1 | B2: 1A | D2: Cottage | E2: Mead Family trust | F2: 1 Yornitj Grove | G2: Witchcliffe | H2: WA | I2: 6286 | J2: 36 | K2: 0.036 | L2: 8.352 | N2: 0 | P2: Y | Q2: N | R2: N | S2: UC | T2: 0 | U2: 0.72 | V2: 0457 578 078 | W2: 0476919881 | X2: nicholasjamesmead@gmail.co | Z2: 45292 | AA2: Current
A3: 2 | B3: 1A | D3: Cottage | E3: Margareta Roeck | F3: 3 Yornitj Grove | G3: Witchcliffe | H3: WA | I3: 6286 | J3: 36 | K3: 0.036 | L3: 8.352 | N3: 0 | P3: Y | Q3: N | R3: N | S3: UC | T3: 0 | U3: 0.72 | V3: 0416732634 | X3: maroeck@gmail.com | Z3: 45292 | AA3: Current | AB3: 45792
A4: 3 | B4: 1A | C4: 50002872 | D4: Cottage | E4: Alexander Hughes | F4: 5 Yornitj Grove | G4: Witchcliffe | H4: WA | I4: 6286 | J4: 37 | K4: 0.037 | L4: 8.584 | N4: 0 | P4: Y | Q4: N | R4: N | S4: O | T4: 0 | U4: 0.72 | V4: 0424154036 | X4: emailalexhughes@gmail.com | Z4: 45292 | AA4: Current
A5: 4 | B5: 1A | C5: 50002869 | D5: Cottage | E5: Paul Jurjevich & Trish Rushton | F5: 7 Yornitj Grove | G5: Witchcliffe | H5: WA | I5: 6286 | J5: 38 | K5: 0.038 | L5: 8.816 | M5: Symo 5.0 | N5: 8.816 | O5: 6.64 | P5: Y | Q5: Y | R5: Y | S5: O | T5: 4.7808 | U5: 0.72 | V5: 0412261482 | W5: 0403732723 | X5: mulloway9@icloud.com | Z5: 45292 | AA5: Current
A6: 5 | B6: 1A | C6: 50002879 | D6: Cottage | E6: Dwyer | F6: 9 Yornitj Grove | G6: Witchcliffe | H6: WA | I6: 6286 | J6: 39 | K6: 0.039 | L6: 9.048 | M6: Symo 5.0 | N6: 9.048 | O6: 6.4 | P6: Y | Q6: Y | R6: Y | S6: O | T6: 4.608 | U6: 0.72 | V6: 0408744572 | W6: 0437286462 | X6: mammoth@iinet.net.au | Z6: 45292 | AA6: Current
A7: 6 | B7: 1A | C7: 50002865 | D7: Cottage | E7: Gillespie | F7: 11 Yornitj Grove | G7: Witchcliffe | H7: WA | I7: 6286 | J7: 39 | K7: 0.039 | L7: 9.048 | M7: Symo 8.2 | N7: 9.048 | O7: 10.88 | P7: Y | Q7: Y | R7: Y | S7: O | T7: 7.8336 | U7: 0.72 | V7: 0417950370 | W7: 0429196637 | X7: barbaragillespie@iinet.net.au | Z7: 45292 | AA7: Current
A8: 7 | B8: 1A | D8: Cottage | E8: Rio & Alix Healey-­‐Diaz | F8: 13 Yornitj Grove | G8: Witchcliffe | H8: WA | I8: 6286 | J8: 37 | K8: 0.037 | L8: 8.584 | N8: 0 | P8: Y | Q8: N | R8: N | S8: O | T8: 0 | U8: 0.72 | V8: 0425890670 | X8: alixward@gmail.com | Z8: 45292 | AA8: Current
A9: 8 | B9: 1A | C9: 50002846 | D9: Cottage | E9: Marcus Browne & Sook-­‐JaRebecchi | F9: 15 Yornitj Grove | G9: Witchcliffe | H9: WA | I9: 6286 | J9: 36 | K9: 0.036 | L9: 8.352 | M9: Symo 5.0 | N9: 8.352 | O9: 6.6 | P9: Y | Q9: Y | R9: Y | S9: O | T9: 4.752 | U9: 0.72 | V9: 0433290368 | W9: 0448279836 | X9: marcus@mishack.com.au | Z9: 45292 | AA9: Current
A10: 9 | B10: 1A | D10: Cottage | E10: Jasmine Heah | F10: 17 Yornitj Grove | G10: Witchcliffe | H10: WA | I10: 6286 | J10: 36 | K10: 0.036 | L10: 8.352 | N10: 0 | P10: Y | Q10: N | R10: N | S10: O | T10: 0 | U10: 0.72 | V10: 0408323274 | X10: jasmine_heah@hotmail.com | Z10: 45292 | AA10: Current
A11: 10 | B11: 1A | D11: Family | E11: Pernille Stent | F11: 51 Mardo Drive | G11: Witchcliffe | H11: WA | I11: 6286 | J11: 53 | K11: 0.053 | L11: 12.296 | M11: Symo 5.0 | N11: 12.296 | O11: 6.4 | P11: Y | Q11: Y | R11: Y | S11: O | T11: 4.608 | U11: 0.72 | V11: 0410416005 | X11: pernille@designbutton.net.au | Z11: 45292 | AA11: Current
A12: 11 | B12: 1A | C12: 50002848 | D12: Family | E12: Levi Holden | F12: 49 Mardo Drive | G12: Witchcliffe | H12: WA | I12: 6286 | J12: 52 | K12: 0.052 | L12: 12.064 | M12: Symo 5.0 | N12: 12.064 | O12: 6.4 | P12: Y | Q12: Y | R12: Y | S12: O | T12: 4.608 | U12: 0.72 | V12: 0427444150 | X12: levi.holden@optusnet.com.au | Z12: 45292 | AA12: Current
A13: 12 | B13: 1A | D13: Family | E13: Matt & Kate Shaw | F13: 47 Mardo Drive | G13: Witchcliffe | H13: WA | I13: 6286 | J13: 52 | K13: 0.052 | L13: 12.064 | N13: 0 | P13: Y | Q13: N | R13: N | S13: UC | T13: 0 | U13: 0.72 | V13: 0428088590 | W13: 0431001084 | X13: shaw76@hotmail.co.uk | Z13: 45292 | AA13: Current
A14: 13 | B14: 1A | C14: 50002739 | D14: Family | E14: Peter Froehlich & Lydia Walzel | F14: 45 Mardo Drive | G14: Witchcliffe | H14: WA | I14: 6286 | J14: 52 | K14: 0.052 | L14: 12.064 | M14: Symo 10.0 | N14: 12.064 | O14: 12.8 | P14: Y | Q14: Y | R14: Y | S14: O | T14: 9.216 | U14: 0.72 | V14: 0418946078 | W14: 0419928925 | X14: froehlich.fp@gmail.com | Z14: 45292 | AA14: Current
A15: 14 | B15: 1A | D15: Family | E15: Priscila Goncalves | F15: 43 Mardo Drive | G15: Witchcliffe | H15: WA | I15: 6286 | J15: 52 | K15: 0.052 | L15: 12.064 | M15: Symo 10.0 | N15: 12.064 | O15: 13.2 | P15: Y | Q15: Y | R15: N | S15: UC | T15: 9.504 | U15: 0.72 | V15: 0475716267 | W15: 0475716400 | X15: diego.barneche@ymail.com | Z15: 45292 | AA15: Current
A16: 15 | B16: 1A | D16: Family | E16: Jeﬀ & Jo Thierfelder | F16: 41 Mardo Drive | G16: Witchcliffe | H16: WA | I16: 6286 | J16: 53 | K16: 0.053 | L16: 12.296 | N16: 0 | P16: Y | Q16: N | R16: N | S16: UC | T16: 0 | U16: 0.72 | V16: 0409770316 | W16: 0421589548 | X16: jeﬀ.thierfelder@iinet.net.au | Z16: 45292 | AA16: Current
A17: 16 | B17: 1A | C17: 50002855 | D17: Family | E17: Libby Davy | F17: 3 Mannitj Place | G17: Witchcliffe | H17: WA | I17: 6286 | J17: 55 | K17: 0.055 | L17: 12.76 | M17: Symo 5.0 | N17: 12.76 | O17: 6.6 | P17: Y | Q17: Y | R17: Y | S17: O | T17: 4.752 | U17: 0.72 | V17: 0413993452 | X17: libby@humanbells.com | Z17: 45292 | AA17: Current
A18: 17 | B18: 1A | C18: 50002877 | D18: Family | E18: Henry & Jo Weldon | F18: 5 Mannitj Place | G18: Witchcliffe | H18: WA | I18: 6286 | J18: 55 | K18: 0.055 | L18: 12.76 | M18: Symo 8.2 | N18: 12.76 | O18: 10.9 | P18: Y | Q18: Y | R18: Y | S18: O | T18: 7.848 | U18: 0.72 | V18: 0407076552 | W18: 0407388196 | X18: henryweldon90@gmail.com | Z18: 45292 | AA18: Current
A19: 18 | B19: 1A | D19: Family | E19: Liz Kirk | F19: 7 Mannitj Place | G19: Witchcliffe | H19: WA | I19: 6286 | J19: 55 | K19: 0.055 | L19: 12.76 | N19: 0 | Q19: N | R19: N | S19: V | T19: 0 | U19: 0.72 | V19: 0408751379 | X19: lizk@beyondergo.com.au | Z19: 45292 | AA19: Current
A20: 19 | B20: 1A | C20: 50002864 | D20: Family | E20: Lindy Dunlop | F20: 9 Mannitj Place | G20: Witchcliffe | H20: WA | I20: 6286 | J20: 55 | K20: 0.055 | L20: 12.76 | M20: Symo 10.0 | N20: 12.76 | O20: 12.8 | P20: Y | Q20: Y | R20: Y | S20: O | T20: 9.216 | U20: 0.72 | V20: 0493385725 | X20: lindyjdunlop@hotmail.com | Z20: 45292 | AA20: Current
A21: 20 | B21: 1A | C21: 50002710 | D21: Groupie | E21: Elke Light | F21: 30 Kulbardi Way | G21: Witchcliffe | H21: WA | I21: 6286 | J21: 26 | K21: 0.026 | L21: 6.032 | M21: Symo 5.0 | N21: 6.032 | O21: 6.4 | P21: Y | Q21: Y | R21: Y | S21: O | T21: 4.608 | U21: 0.72 | V21: 0439968661 | X21: lightelke@gmail.com | Z21: 45292 | AA21: Current
A22: 21 | B22: 1A | C22: 50002719 | D22: Groupie | E22: Deborah Woodman | F22: 28 Kulbardi Way | G22: Witchcliffe | H22: WA | I22: 6286 | J22: 26 | K22: 0.026 | L22: 6.032 | M22: Symo 5.0 | N22: 6.032 | O22: 6.4 | P22: Y | Q22: Y | R22: Y | S22: O | T22: 4.608 | U22: 0.72 | V22: 0456121155 | X22: woodmandj55@gmail.com | Z22: 45292 | AA22: Current
A23: 22 | B23: 1A | C23: 50002876 | D23: Groupie | E23: Carrie & Warrick Goldsmith | F23: 26 Kulbardi Way | G23: Witchcliffe | H23: WA | I23: 6286 | J23: 26 | K23: 0.026 | L23: 6.032 | M23: Symo 5.0 | N23: 6.032 | O23: 6.4 | P23: Y | Q23: Y | R23: Y | S23: O | T23: 4.608 | U23: 0.72 | V23: 0499270453 | W23: 0447110831 | X23: carrieandwarrick@gmail.com | Z23: 45292 | AA23: Current
A24: 23 | B24: 1A | C24: 50002860 | D24: Groupie | E24: Clyde Huxtable | F24: 24 Kulbardi Way | G24: Witchcliffe | H24: WA | I24: 6286 | J24: 26 | K24: 0.026 | L24: 6.032 | M24: Symo 5.0 | N24: 6.032 | O24: 6.4 | P24: Y | Q24: Y | R24: Y | S24: O | T24: 4.608 | U24: 0.72 | V24: 0406351722 | X24: hotfire1948@hotmail.com | Z24: 45292 | AA24: Current
A25: 24 | B25: 1A | D25: Groupie | E25: Helen Rose | F25: 22 Kulbardi Way | G25: Witchcliffe | H25: WA | I25: 6286 | J25: 28 | K25: 0.028 | L25: 6.496 | N25: 0 | P25: Y | Q25: N | R25: N | S25: UC | T25: 0 | U25: 0.72 | V25: 0437445630 | X25: rosebunch5@gmail.com | Z25: 45292 | AA25: Current
A26: BESS | B26: 1A | C26: 40002686 | E26: BESS Powerpack 232kWh | J26: 1000 | K26: 1 | N26: 0 | T26: 0 | U26: 0.72
A27: EV | B27: 1A | C27: 40002693 | D27: N/A | E27: EV Charger | G27: Witchcliffe | H27: WA | I27: 6286 | K27: 0 | L27: 0 | N27: 0 | P27: Y | Q27: N | R27: Y | T27: 0 | U27: 0.72
A28: CS | B28: 1A | D28: N/A | E28: Common Services MSB | G28: Witchcliffe | H28: WA | I28: 6286 | K28: 0 | L28: 0 | N28: 0 | P28: Y | Q28: N | R28: Y | T28: 0 | U28: 0.72
A29: DB1 | B29: 1A | K29: 0 | N29: 0 | T29: 0
A30: DB2 | B30: 1A | K30: 0 | N30: 0 | T30: 0
A31: 1 | B31: 1B | C31: 50003409 | D31: Cottage | E31: Susan Gibson | F31: 78 Kulbardi Way | G31: Witchcliffe | H31: WA | I31: 6286 | J31: 42 | K31: =Table_Household_Alloc[[#This Row],[Unit Entitlement]]/1000 -> 0.042 | L31: =(J31/1000)*232 -> 9.744 | M31: Symo 5.0 | N31: =IF(Table_Household_Alloc[[#This Row],[PV Installed]]="Y",1,0)*Table_Household_Alloc[[#This Row],[Calculated Battery Allocation (kWh)]] -> 9.744 | O31: 5 | P31: Y | Q31: Y | R31: Y | S31: O
A32: 2 | B32: 1B | C32: 50003436 | D32: Cottage | E32: Karen Majer & Boyd Wykes | F32: 76 Kulbardi Way | G32: Witchcliffe | H32: WA | I32: 6286 | J32: 43 | K32: =Table_Household_Alloc[[#This Row],[Unit Entitlement]]/1000 -> 0.043 | L32: =(J32/1000)*232 -> 9.976 | M32: Symo 8.2 | N32: =IF(Table_Household_Alloc[[#This Row],[PV Installed]]="Y",1,0)*Table_Household_Alloc[[#This Row],[Calculated Battery Allocation (kWh)]] -> 9.976 | O32: 8.2 | P32: Y | Q32: Y | R32: Y | S32: O
A33: 3 | B33: 1B | C33: 50004064 | D33: Cottage | E33: Susan Hardy | F33: 74 Kulbardi Way | G33: Witchcliffe | H33: WA | I33: 6286 | J33: 43 | K33: =Table_Household_Alloc[[#This Row],[Unit Entitlement]]/1000 -> 0.043 | L33: =(J33/1000)*232 -> 9.976 | M33: Symo 5.0 | N33: =IF(Table_Household_Alloc[[#This Row],[PV Installed]]="Y",1,0)*Table_Household_Alloc[[#This Row],[Calculated Battery Allocation (kWh)]] -> 9.976 | O33: 5 | P33: Y | Q33: Y | R33: Y | S33: O
A34: 4 | B34: 1B | C34: 50003414 | D34: Cottage | E34: Jennie McCormack | F34: 72 Kulbardi Way | G34: Witchcliffe | H34: WA | I34: 6286 | J34: 45 | K34: =Table_Household_Alloc[[#This Row],[Unit Entitlement]]/1000 -> 0.045 | L34: =(J34/1000)*232 -> 10.44 | M34: Symo 5.0 | N34: =IF(Table_Household_Alloc[[#This Row],[PV Installed]]="Y",1,0)*Table_Household_Alloc[[#This Row],[Calculated Battery Allocation (kWh)]] -> 10.44 | O34: 5 | P34: Y | Q34: Y | R34: Y | S34: O
A35: 5 | B35: 1B | C35: 50003389 | D35: Cottage | E35: Michael & Britta Sorensen | F35: 70 Kulbardi Way | G35: Witchcliffe | H35: WA | I35: 6286 | J35: 46 | K35: =Table_Household_Alloc[[#This Row],[Unit Entitlement]]/1000 -> 0.046 | L35: =(J35/1000)*232 -> 10.672 | M35: Symo 8.2 | N35: =IF(Table_Household_Alloc[[#This Row],[PV Installed]]="Y",1,0)*Table_Household_Alloc[[#This Row],[Calculated Battery Allocation (kWh)]] -> 10.672 | O35: 8.2 | P35: Y | Q35: Y | R35: Y | S35: O
A36: 6 | B36: 1B | C36: 50002969 | D36: Cottage | E36: Toni Aslett | F36: 68 Kulbardi Way | G36: Witchcliffe | H36: WA | I36: 6286 | J36: 50 | K36: =Table_Household_Alloc[[#This Row],[Unit Entitlement]]/1000 -> 0.05 | L36: =(J36/1000)*232 -> 11.6 | M36: Symo 8.2 | N36: =IF(Table_Household_Alloc[[#This Row],[PV Installed]]="Y",1,0)*Table_Household_Alloc[[#This Row],[Calculated Battery Allocation (kWh)]] -> 11.6 | O36: 8.2 | P36: Y | Q36: Y | R36: Y | S36: O
A37: 7 | B37: 1B | C37: 50002951 | D37: Cottage | E37: Bridget Bolitho | F37: 66 Kulbardi Way | G37: Witchcliffe | H37: WA | I37: 6286 | J37: 52 | K37: =Table_Household_Alloc[[#This Row],[Unit Entitlement]]/1000 -> 0.052 | L37: =(J37/1000)*232 -> 12.064 | M37: Symo 5.0 | N37: =IF(Table_Household_Alloc[[#This Row],[PV Installed]]="Y",1,0)*Table_Household_Alloc[[#This Row],[Calculated Battery Allocation (kWh)]] -> 12.064 | O37: 5 | P37: Y | Q37: Y | R37: Y | S37: O
A38: 8 | B38: 1B | C38: 50002959 | D38: Family | E38: Shereen & Hamish Jolly | F38: 64 Kulbardi Way | G38: Witchcliffe | H38: WA | I38: 6286 | J38: 69 | K38: =Table_Household_Alloc[[#This Row],[Unit Entitlement]]/1000 -> 0.069 | L38: =(J38/1000)*232 -> 16.008 | M38: Symo 6.0 | N38: =IF(Table_Household_Alloc[[#This Row],[PV Installed]]="Y",1,0)*Table_Household_Alloc[[#This Row],[Calculated Battery Allocation (kWh)]] -> 16.008 | O38: 6 | P38: Y | Q38: Y | R38: Y | S38: O
A39: 9 | B39: 1B | D39: Family | E39: Phillip Crockford & Wendy Davis | F39: 62 Kulbardi Way | G39: Witchcliffe | H39: WA | I39: 6286 | J39: 55 | K39: =Table_Household_Alloc[[#This Row],[Unit Entitlement]]/1000 -> 0.055 | L39: =(J39/1000)*232 -> 12.76 | M39: Symo 10.0 | N39: =IF(Table_Household_Alloc[[#This Row],[PV Installed]]="Y",1,0)*Table_Household_Alloc[[#This Row],[Calculated Battery Allocation (kWh)]] -> 0 | P39: N | Q39: N | R39: N | S39: V
A40: 10 | B40: 1B | C40: 50003420 | D40: Family | E40: Stefan & Jennifer Widmer | F40: 60 Kulbardi Way | G40: Witchcliffe | H40: WA | I40: 6286 | J40: 57 | K40: =Table_Household_Alloc[[#This Row],[Unit Entitlement]]/1000 -> 0.057 | L40: =(J40/1000)*232 -> 13.224 | M40: Symo 5.0 | N40: =IF(Table_Household_Alloc[[#This Row],[PV Installed]]="Y",1,0)*Table_Household_Alloc[[#This Row],[Calculated Battery Allocation (kWh)]] -> 13.224 | O40: 5 | P40: Y | Q40: Y | R40: Y | S40: O
...

Sheet Amanda Energy
A1: Cluster | B1: Year | C1: Month | D1: Consumption_kWh | E1: Export_kWh | F1: Amanda_consumption_incl_GST | G1: Amanda_export_buyback_incl_GST | H1: Daily_Supply_incl_GST | I1: Other_Fees_incl_GST | J1: Total_incl_GST
A2: 1A | B2: 2025 | C2: 01 | D2: 33.93 | E2: 11281.06 | F2: 10.16 | G2: -434.32 | H2: 170.5 | I2: 15.54 | J2: -238.12
A3: 1A | B3: 2025 | C3: 02 | D3: 9.73 | E3: 10654.83 | F3: 2.92 | G3: -410.21 | H3: 154 | I3: 12.85 | J3: -240.45
A4: 1A | B4: 2025 | C4: 03 | D4: 41.84 | E4: 11239.82 | F4: 12.52 | G4: -432.73 | H4: 170.5 | I4: 16.76 | J4: -232.95
A5: 1B | B5: 2025 | C5: 01 | D5: 12.07 | E5: 17535.52 | F5: 3.62 | G5: -675.11 | H5: 170.5 | I5: 18.04 | J5: -482.96
A6: 1B | B6: 2025 | C6: 02 | D6: 13.33 | E6: 13942.64 | F6: 3.99 | G6: -536.79 | H6: 154 | I6: 16.57 | J6: -362.23
A7: 1B | B7: 2025 | C7: 03 | D7: 14.9 | E7: 14891.96 | F7: 4.46 | G7: -573.34 | H7: 170.5 | I7: 18.59 | J7: -379.8
A8: 1C | B8: 2025 | C8: 01 | D8: 44.48 | E8: 13074.94 | F8: 13.32 | G8: -503.38 | H8: 170.5 | I8: 22.22 | J8: -297.34
A9: 1C | B9: 2025 | C9: 02 | D9: 46.06 | E9: 12380.74 | F9: 13.78 | G9: -476.66 | H9: 154 | I9: 19.29 | J9: -289.59
A10: 1C | B10: 2025 | C10: 03 | D10: 17.99 | E10: 14328.95 | F10: 5.38 | G10: -551.66 | H10: 170.5 | I10: 19.8 | J10: -355.98
A11: 2A | B11: 2025 | C11: 01 | D11: 68.36 | E11: 9864.97 | F11: 21.46 | G11: -379.8 | H11: 178.78 | I11: 0 | J11: -179.55
A12: 2A | B12: 2025 | C12: 02 | D12: 60.15 | E12: 9289.63 | F12: 18.89 | G12: -357.64 | H12: 161.48 | I12: 0 | J12: -177.28
A13: 2B | B13: 2025 | C13: 01 | D13: 25.59 | E13: 13715.2 | F13: 8.04 | G13: -528.04 | H13: 178.78 | I13: 0 | J13: -341.22
... A24: 3C | B24: 2025 | C24: 03 | D24: 219.33 | E24: 5174.58 | F24: 68.86 | G24: -199.22 | H24: 178.78 | I24: 0 | J24: 48.42

Sheet reading-import
A1: Lot | B1: cluster | C1: Meter# | D1: 1/2/2024 | E1: 1/5/2024 | F1: 1/8/2024 | G1: 1/10/2024 | H1: 9/10/2024 | I1: 1/1/2025 | J1: 1/3/2025 | K1: 01/04/2025 | L1: 01/05/2025
A2: 1 | B2: 1A | C2: 50002845 | D2: 0 | E2: 0 | F2: 0 | H2: 0 | I2: 5 | J2: 12 | K2: 31
A3: 2 | B3: 1A | C3: 50002862 | D3: 154 | E3: 193 | F3: 200 | H3: 217 | I3: 252 | J3: 302 | K3: 342
A4: 3 | B4: 1A | C4: 50002872 | D4: 3330 | E4: 4152 | F4: 5885 | G4: 7147 | I4: 8271 | J4: 8830 | K4: 9141
A5: 4 | B5: 1A | C5: 50002869 | D5: 1658.51 | E5: 2242 | F5: 3297.66 | G5: 4012 | I5: 4542 | J5: 4855 | K5: 5037
A6: 5 | B6: 1A | C6: 50002879 | D6: 2500 | E6: 2698 | F6: 3033.57 | G6: 3287 | I6: 3545 | J6: 3673 | K6: 3743
A7: 6 | B7: 1A | C7: 50002865 | D7: 4614 | E7: 5036 | F7: 6545.69 | G7: 7860 | I7: 8639 | J7: 8918 | K7: 9246
A8: 7 | B8: 1A | C8: 50002887 | D8: 5556 | E8: 6178 | F8: 7086 | H8: 7678 | I8: 8272 | J8: 8725 | K8: 8864
A9: 8 | B9: 1A | C9: 50002846 | D9: 17 | E9: 62 | F9: 1347 | G9: 2312 | I9: 3006 | J9: 3404 | K9: 3589
A10: 9 | B10: 1A | C10: 50002885 | D10: 9455 | E10: 10505 | F10: 11763 | H10: 12689 | I10: 13606 | J10: 14226 | K10: 14595
A11: 10 | B11: 1A | C11: 50002850 | D11: 2297 | E11: 2548 | F11: 3196.09 | G11: 3549 | I11: 3930 | J11: 4324 | K11: 4514
A12: 11 | B12: 1A | C12: 50002848 | D12: 1025 | E12: 1059 | F12: 1104.64 | G12: 1138 | I12: 1173 | J12: 1194 | K12: 1203
A13: 12 | B13: 1A | C13: 50002847 | D13: 0 | E13: 0 | F13: 0 | H13: 0 | I13: 34 | J13: 42 | K13: 43
A14: 13 | B14: 1A | C14: 50002739 | D14: 3754 | E14: 4117 | F14: 4598.5 | G14: 4840 | I14: 5168 | J14: 5392 | K14: 5504
A15: 14 | B15: 1A | C15: 50002709 | D15: 0 | E15: 2 | F15: 26 | H15: 95 | I15: 213 | J15: 501 | K15: 667
A16: 15 | B16: 1A | C16: 50002714 | D16: 426 | E16: 570 | F16: 570 | H16: 571 | I16: 571 | J16: 571 | K16: 571
A17: 16 | B17: 1A | C17: 50002855 | D17: 455 | E17: 907 | F17: 1537.61 | G17: 2060 | I17: 2536 | J17: 2846 | K17: 3048
A18: 17 | B18: 1A | C18: 50002877 | D18: 11075 | E18: 12991 | F18: 16647.34 | G18: 18767 | I18: 20977 | J18: 22060 | K18: 22723
A19: 18 | B19: 1A | D19: 0 | E19: 0 | F19: 0 | H19: 0 | I19: 0 | J19: 0
A20: 19 | B20: 1A | C20: 50002864 | D20: 2270 | E20: 2483 | F20: 2819.8 | G20: 3000 | I20: 3203 | J20: 3327 | K20: 3415
A21: 20 | B21: 1A | C21: 50002710 | D21: 2601 | E21: 2781 | F21: 3120.21 | G21: 3389 | I21: 3644 | J21: 3772 | K21: 3852
A22: 21 | B22: 1A | C22: 50002719 | D22: 1225 | E22: 1316 | F22: 1471.61 | G22: 1590 | I22: 1682 | J22: 1735 | K22: 1774
A23: 22 | B23: 1A | C23: 50002876 | D23: 4040 | E23: 4239 | F23: 4589.33 | G23: 4843 | I23: 5052 | J23: 5169 | K23: 5246
A24: 23 | B24: 1A | C24: 50002860 | D24: 2297 | E24: 2429 | F24: 2786.87 | G24: 3041 | I24: 3181 | J24: 3257 | K24: 3312
A25: 24 | B25: 1A | C25: 50002649 | D25: 0 | E25: 0 | F25: 0 | H25: 18 | I25: 27 | J25: 38 | K25: 41
A26: BESS | B26: 1A | C26: 40002686 | D26: 2686.84 | E26: 14090.38 | F26: 32077.16 | G26: 44721 | I26: 59297 | J26: 67826 | K26: 73298
A27: EV | B27: 1A | C27: 40002693 | D27: 0 | E27: 209.39 | F27: 1646.88 | G27: 2831 | I27: 4535 | J27: 6152 | K27: 7172
A28: CS | B28: 1A | C28: 50002858 | D28: 2819.46 | E28: 3565.94 | F28: 4127.37 | G28: 4326 | I28: 4913 | J28: 5343 | K28: 5527
A29: DB1 | B29: 1A | C29: 40002852 | I29: 157 | J29: 166 | K29: 171
A30: DB2 | B30: 1A | C30: 40002693 | I30: 232 | J30: 251 | K30: 262
A31: 1 | B31: 1B | C31: 50003409 | D31: 4530 | E31: 4701 | F31: 5443.32 | H31: 5990.04 | I31: 6200 | J31: 6302 | K31: 6361
A32: 2 | B32: 1B | C32: 50003436 | D32: 1679 | E32: 2331 | F32: 3416.3 | H32: 3923.86 | I32: 4133 | J32: 4305 | K32: 4403
A33: 3 | B33: 1B | C33: 50004064 | D33: 594 | E33: 1137 | F33: 1765.3 | H33: 2232.7 | I33: 2521 | J33: 2701 | K33: 2809
A34: 4 | B34: 1B | C34: 50003414 | D34: 102 | E34: 114 | F34: 126 | H34: 156 | I34: 188 | J34: 268 | K34: 330
A35: 5 | B35: 1B | C35: 50003389 | D35: 10220 | E35: 10700 | F35: 11494.07 | H35: 12012.6 | I35: 12384 | J35: 12657 | K35: 12840
A36: 6 | B36: 1B | C36: 50002969 | D36: 3937 | E36: 4341 | F36: 5453.28 | H36: 6621.05 | I36: 7108 | J36: 7388 | K36: 7527
A37: 7 | B37: 1B | C37: 50002951 | D37: 6063 | E37: 6514 | F37: 7105.58 | H37: 8010.78 | I37: 8532 | J37: 8816 | K37: 8960
A38: 8 | B38: 1B | C38: 50002959 | D38: 2378 | E38: 3049 | F38: 3644.67 | H38: 4022.29 | I38: 4410 | J38: 4764 | K38: 5114
A39: 9 | B39: 1B | D39: 0 | E39: 0 | F39: 0
A40: 10 | B40: 1B | C40: 50003420 | D40: 4776 | E40: 5124 | F40: 5898.31 | H40: 6484.91 | I40: 6876 | J40: 7104 | K40: 7203
...

Sheet reading-export
A1: Lot | B1: cluster | C1: Meter# | D1: 1/2/2024 | E1: 1/5/2024 | F1: 1/8/2024 | G1: 1/10/2024 | H1: 9/10/2024 | I1: 1/1/2025 | J1: 1/3/2025 | K1: 01/04/2025 | L1: 01/05/2025
A2: 1 | B2: 1A | C2: 50002845 | D2: 0 | E2: 0 | J2: 0
A3: 2 | B3: 1A | C3: 50002862 | D3: 0 | E3: 0 | J3: 0
A4: 3 | B4: 1A | C4: 50002872 | D4: 0 | E4: 0 | G4: 0 | I4: 0 | J4: 0 | K4: 0
A5: 4 | B5: 1A | C5: 50002869 | D5: 1100 | E5: 3828 | F5: 5318.8 | G5: 6465 | I5: 9031 | J5: 10612 | K5: 11476
A6: 5 | B6: 1A | C6: 50002879 | D6: 4250 | E6: 7203 | F6: 8765.43 | G6: 10052 | I6: 12884 | J6: 14647 | K6: 15571
A7: 6 | B7: 1A | C7: 50002865 | D7: 5911 | E7: 10438 | F7: 12556.76 | G7: 14094 | I7: 18121 | J7: 20965 | K7: 22324
A8: 7 | B8: 1A | C8: 50002887 | D8: 0 | E8: 0 | J8: 0
A9: 8 | B9: 1A | C9: 50002846 | D9: 0 | E9: 0 | G9: 0 | I9: 2569 | J9: 4165 | K9: 5027
A10: 9 | B10: 1A | C10: 50002885 | D10: 0 | E10: 0 | J10: 0
A11: 10 | B11: 1A | D11: 12347 | E11: 15095 | F11: 16643.58 | G11: 17815 | I11: 20316 | J11: 21130 | K11: 22009
A12: 11 | B12: 1A | C12: 50002848 | D12: 13447 | E12: 16509 | F12: 18262.11 | G12: 19650 | I12: 22593 | J12: 24391 | K12: 25470
A13: 12 | B13: 1A | C13: 50002847 | D13: 0 | E13: 0 | J13: 0
A14: 13 | B14: 1A | C14: 50002739 | D14: 25717 | E14: 30627 | F14: 33475.85 | G14: 36023 | I14: 41072 | J14: 44319 | K14: 46143
A15: 14 | B15: 1A | C15: 50002709 | D15: 0 | E15: 0 | J15: 2399 | K15: 3999
A16: 15 | B16: 1A | C16: 50002714 | D16: 0 | E16: 0 | J16: 0
A17: 16 | B17: 1A | C17: 50002855 | D17: 0 | E17: 2568 | F17: 4134.29 | G17: 5245 | I17: 7804 | J17: 9378 | K17: 10186
A18: 17 | B18: 1A | C18: 50002877 | D18: 4293 | E18: 7088 | F18: 8027 | G18: 9059 | I18: 12029 | J18: 14003 | K18: 14923
A19: 18 | B19: 1A | D19: 0 | E19: 0 | J19: 0
A20: 19 | B20: 1A | C20: 50002864 | D20: 26703 | E20: 32368 | F20: 35423.8 | G20: 38020 | I20: 43757 | J20: 47349 | K20: 49180
A21: 20 | B21: 1A | C21: 50002710 | D21: 3903 | E21: 6356 | F21: 7464.47 | G21: 8589 | I21: 11511 | J21: 13341 | K21: 14162
A22: 21 | B22: 1A | C22: 50002719 | D22: 4515 | E22: 7478 | F22: 9166.34 | G22: 10489 | I22: 13350 | J22: 15149 | K22: 16096
A23: 22 | B23: 1A | C23: 50002876 | D23: 4040 | E23: 6783 | F23: 8314.63 | G23: 9617 | I23: 12269 | J23: 13938 | K23: 14832
A24: 23 | B24: 1A | C24: 50002860 | D24: 5498 | E24: 8307 | F24: 9976.39 | G24: 11307 | I24: 14010 | J24: 15720 | K24: 16609
A25: 24 | B25: 1A | C25: 50002649 | D25: 0 | E25: 0 | J25: 0
A26: BESS | B26: 1A | C26: 40002686 | D26: 1833.14 | E26: 11017.34 | F26: 26071.13 | G26: 36413 | I26: 48306 | J26: 55361 | K26: 59831
A27: EV | B27: 1A | C27: 40002693 | D27: 0 | E27: 0 | F27: 0 | K27: 0
A28: CS | B28: 1A | C28: 50002858 | D28: 0 | E28: 0 | F28: 0 | G28: 0 | I28: 0 | J28: 0 | K28: 0
A29: DB1 | B29: 1A | C29: 40002852
A30: DB2 | B30: 1A | C30: 40002693
A31: 1 | B31: 1B | C31: 50003409 | D31: 3498 | E31: 5938 | F31: 7210.69 | H31: 8291.68 | I31: 10303 | J31: 11728 | K31: 12488
A32: 2 | B32: 1B | C32: 50003436 | D32: 265 | E32: 4070 | F32: 5442.96 | H32: 7233.44 | I32: 11104 | J32: 13586 | K32: 14779
A33: 3 | B33: 1B | C33: 50004064 | D33: 0 | E33: 0 | F33: 684.6 | H33: 1696.37 | I33: 3777 | J33: 5275 | K33: 5973
A34: 4 | B34: 1B | C34: 50003414 | D34: 0 | E34: 0 | F34: 458 | H34: 1460.91 | I34: 4228 | J34: 5871 | K34: 6615
A35: 5 | B35: 1B | C35: 50003389 | D35: 5814 | E35: 9155 | F35: 10239.42 | H35: 11614.69 | I35: 15198 | J35: 17553 | K35: 18600
A36: 6 | B36: 1B | C36: 50002969 | D36: 854 | E36: 4535 | F36: 5754.6 | H36: 7410.18 | I36: 11083 | J36: 13497 | K36: 14615
A37: 7 | B37: 1B | C37: 50002951 | D37: 3559 | E37: 5963 | F37: 7249.59 | H37: 8203.86 | I37: 10036 | J37: 11379 | K37: 12093
A38: 8 | B38: 1B | C38: 50002959 | D38: 17 | E38: 2480 | F38: 3838.25 | H38: 5415.75 | I38: 8407 | J38: 10346 | K38: 11149
A39: 9 | B39: 1B | D39: 0 | E39: 0 | F39: 0
A40: 10 | B40: 1B | C40: 50003420 | D40: 12138 | E40: 14501 | F40: 15561 | H40: 16512.4 | I40: 18452 | J40: 19803 | K40: 20554
...

Sheet Tariff Rates
B1: P2P Charge Rate (Inc. GST) | C1: P2P Export Rate (Inc. GST) | D1: Common Charge Rate (Inc. GST) | E1: Grid Import Rate (Inc. GST) | F1: Grid Export Rate (Inc. GST) | G1: EV Charger Sale to consumer Rate (Inc. GST) | H1: Chargefox Commission take on EV Consumption % (Inc. GST) | I1: Chargefox Commission (Inc GST) | J1: P2P Energy Invasion Charge (Inc. GST) | K1: P2P Energy Borrow Revenue (Inc. GST) | L1: P2P rate for lots with no export (Inc. GST)
A2: c/kWh | B2: 22 | C2: -22 | D2: 22 | E2: 30 | F2: =-3.5*1.1 -> -3.85 | G2: -65 | H2: -0.05 | I2: =-G2*H2 -> -3.25 | J2: 2 | K2: -2 | L2: 36
A3: $/kWh | B3: =B2/100 -> 0.22 | C3: =C2/100 -> -0.22 | D3: =D2/100 -> 0.22 | E3: 0.3 | F3: =F2/100 -> -0.0385 | G3: =G2/100 -> -0.65 | H3: -0.05 | I3: =I2/100 -> -0.0325 | J3: =J2/100 -> 0.02 | K3: =K2/100 -> -0.02 | L3: =L2/100 -> 0.36
B6: SwitchdIn Cost ($ inc. GST) | C6: Chargefox Daily Supply Charge/cluster | D6: Element47 Embedded Network Daily Supply Charges
A7: $/yr | B7: 55 | C7: 858 | D7: 80.3
A8: $/day | B8: =B7/365 -> 0.15068493 | C8: =C7/365 -> 2.3506849 | D8: =D7/365 -> 0.22
B10: Element47 Invoicing Fee
A11: $/Invoice | B11: 1.1

Sheet Energy billing Mastersheet
B1: 1A | C1: billing period | F1: =DATE(2025,F2,1) -> 45658 | H1: =DATE(2025,H2+1,0) -> 45747
F2: 01 | G2: 02 | H2: 03
C3: Number of Days | F3: =DAY(DATE(2024,F2+1,0)) -> 31 | G3: =DAY(DATE(2024,G2+1,0)) -> 29 | H3: =DAY(DATE(2024,H2+1,0)) -> 31 | I3: =N3 -> 90 | J3: =N3 -> 90 | K3: =N3 -> 90 | L3: =N3 -> 90 | M3: 1 | N3: =H1-F1+1 -> 90 | P3: Import data | R3: Consumption Energy | AE3: Battery Loss and common services | AQ3: Export data | BK3: EV Charger Reconcillation | BQ3: Combined
A4: Lot | B4: Name | C4: Meter Numbers | D4: Percentage of Unit Entitlement (%) | E4: Stage of Dev. | F4: Amanda Energy Daily Supply Charge ($) | G4: Amanda Energy Daily Supply Charge ($)2 | H4: Amanda Energy Daily Supply Charge ($)3 | I4: Amanda Energy Other fees ($) | J4: SwitchdIn Cost Daily Supply Charge ($) | K4: Chargefox Daily Supply Charge ($) | L4: Element47 Embedded Network Daily Supply Charges | M4: Element47 Embedded Network Invoicing Fees | N4: Total supply | O4: 1st day of reporting period: import | P4: Last day of reporting period: import | Q4: Total Consumption Import (kWh) | R4: Total Daily Average Consumptio for Billing Period (kWh) | S4: Percentage of Total Import for Billing Period (%) | T4: Daily Battery allowance based on UE% (kWh) | U4: Applicable Battery Allowance Daily Consumption (kWh) | V4: Unused Daily Allowance (kWh) | W4: Unused Daily Allowance % | X4: P2P Import Consumption within Battery Allowance(kWh) | Y4: Energy Exceeding Battery Allowance (kWh) | Z4: Energy Exceeding Battery Allowance % | AA4: Total Cluster Energy Balance for P2P Trading (kWh) | AB4: P2P Import Consumption over Battery Allowance based on Energy Exceeding Allowance % (kWh) | AC4: Total P2P import (kWh) | AD4: Energy Import from Grid (kWh) | AE4: P2P import% | AF4: Cluster's Total Battery Loss (kWh) | AG4: Axillary Battery Losses based upon P2P import % (kWh) | AH4: Cluster's Total Common Services (kWh) | AI4: Common Services based on Split per Unit Entitlement % to battery (kWh) | AJ4: Axillary Battery Loss Charges at P2P Rates based upon P2P import % ($) | AK4: Common Services Cost Split per Unit Entitlement at P2P rate ($) | AL4: P2P Import Cost ($) | AM4: Exceeding Battery Allowance P2P Fee ($) | AN4: Import From Grid Cost ($) | AO4: Total Consumption Cost/Lot | AP4: 1st day of reporting period: export | AQ4: Last day of reporting period: export | AR4: Total Lot Export (kWh) | AS4: Percentage of Total export for Billing Period (%) | AT4: Total Energy Export P2P to battery (kWh) | AU4: Total Cluster Energy Balance for P2P Trading (kWh)2 | AV4: Borrowed Allowance Based on Unused Daily Allowance % (kWh) | AW4: Axillary Battery Losses based upon Adjusted % total export (kWh) | AX4: Common Service based upon % total export to battery (kWh) | AY4: EV Charger based upon % total export to battery (kWh) | AZ4: Therotical Energy Export to Grid (kWh) | BA4: Energy Losses When Export to Grid (kWh) | BB4: Energy Losses When Export to Grid based up % total export (kWh) | BC4: Energy Export to Grid after Losses (kWh) | BD4: Axillary Battery Losses based upon % total export ($) | BE4: Common Service Earning based upon % total export to Load ($) | BF4: EV Charger based upon % total export ($) | BG4: P2P Export Earnings ($) | BH4: Passive Compensation ($) | BI4: Grid Export Earnings ($) | BJ4: Total Export Earnings Per Lot After P2P Battery Energy Storage and Use ($) | BK4: EV Charger Income from Sales Equitable Distribution on UE ($) | BL4: Chargefox Commission on EV Charge Consumption Sales Cost Split by Unit Entitlement ($) | BM4: EV Charger Cost of Electricity Supply at P2P Rates ($) | BN4: Total EV Charger Operating Cost ($) | BO4: Total EV Charger Revenue ($) | BP4: EV Charger Profit per lot owner ($) | BQ4: Energy Invoice Total Charges or Revenue $ | BR4: Date issued | BS4: Date Paid | BT4: Lot
A5: 1 | B5: {=INDEX(Table_Household_Alloc[Owner],MATCH(1,(Table_Household_Alloc[Lot]=A5)*(Table_Household_Alloc[cluster]=$B$1),0))} -> Mead Family trust | C5: {=INDEX(Reading_import[Meter'#],MATCH(1,(Table_Household_Alloc[Lot]=A5)*(Table_Household_Alloc[cluster]=$B$1),0))} -> 50002845 | D5: {=INDEX(Table_Household_Alloc[UE % over Cluster],MATCH(1,(Table_Household_Alloc[Lot]=A5)*(Table_Household_Alloc[cluster]=$B$1),0))} -> 0.036 | E5: {=INDEX(Table_Household_Alloc[Stage of Dev.],MATCH(1,(Table_Household_Alloc[Lot]=A5)*(Table_Household_Alloc[cluster]=$B$1),0))} -> UC | F5: {=INDEX(Amanda_energy[Daily_Supply_incl_GST],MATCH(1,(Amanda_energy[Cluster]=$B$1)*(Amanda_energy[Month]=$F$2),0))/MAX($A:$A)} -> 6.3148148 | G5: {=INDEX(Amanda_energy[Daily_Supply_incl_GST],MATCH(1,(Amanda_energy[Cluster]=$B$1)*(Amanda_energy[Month]=$G$2),0))/MAX($A:$A)} -> 5.7037037 | H5: {=INDEX(Amanda_energy[Daily_Supply_incl_GST],MATCH(1,(Amanda_energy[Cluster]=$B$1)*(Amanda_energy[Month]=$H$2),0))/MAX($A:$A)} -> 6.3148148 | I5: =$J$46/MAX($A:$A) -> 1.6722222 | L5: =$L$3*'Tariff Rates'!$D$8*IF(Table1[[#This Row],[Stage of Dev.]]="V",0,1) -> 19.8 | M5: 1.1 | N5: =SUM(F5:M5) -> 40.905556 | O5: {=INDEX(Reading_import[1/1/2025],MATCH(1,(Reading_import[Lot]=A5)*(Reading_import[cluster]=$B$1),0))} -> 5 | P5: {=INDEX(Reading_import[01/04/2025],MATCH(1,(Reading_import[Lot]=A5)*(Reading_import[cluster]=$B$1),0))} -> 31 | Q5: =Table1[[#This Row],[Last day of reporting period: import]]-Table1[[#This Row],[1st day of reporting period: import]] -> 26 | R5: =Q5/$N$3 -> 0.28888889 | S5: =Q5/$Q$38 -> 0.0028979046 | T5: =IF(Table1[[#This Row],[Stage of Dev.]]="V",0,233*Table1[[#This Row],[Percentage of Unit Entitlement (%)]]) -> 8.388 | U5: =IF(T5>R5,R5,T5) -> 0.28888889 | V5: =Table1[[#This Row],[Daily Battery allowance based on UE% (kWh)]]-Table1[[#This Row],[Applicable Battery Allowance Daily Consumption (kWh)]] -> 8.0991111 | W5: =Table1[[#This Row],[Unused Daily Allowance (kWh)]]/$V$38 -> 0.061954071 | X5: =IF(Table1[[#This Row],[Applicable Battery Allowance Daily Consumption (kWh)]]>Table1[[#This Row],[Total Daily Average Consumptio for Billing Period (kWh)]],Table1[[#This Row],[Total Consumption Import (kWh)]],U5*$N$3) -> 26 | Y5: =IF(Table1[[#This Row],[Applicable Battery Allowance Daily Consumption (kWh)]]>0,ABS(Q5-X5),0) -> 0 | Z5: =IFERROR(Table1[[#This Row],[Energy Exceeding Battery Allowance (kWh)]]/$Y$38,0) -> 0 | AA5: =IF($Y$38-$E$46>0,$Y$38-$E$46,0) -> 835.34 | AB5: =IFERROR(Table1[[#This Row],[Total Cluster Energy Balance for P2P Trading (kWh)]]*Table1[[#This Row],[Energy Exceeding Battery Allowance %]],0) -> 0 | AC5: =Table1[[#This Row],[P2P Import Consumption within Battery Allowance(kWh)]]+Table1[[#This Row],[P2P Import Consumption over Battery Allowance based on Energy Exceeding Allowance % (kWh)]] -> 26 | AD5: =Table1[[#This Row],[Total Consumption Import (kWh)]]-Table1[[#This Row],[Total P2P import (kWh)]] -> 0 | AE5: =IFERROR(Table1[[#This Row],[Total P2P import (kWh)]]/$AC$38,0) -> 0 | AF5: =($Q$32-$AR$32) -> 2476 | AG5: =AF5*AE5 -> 0 | AH5: =SUM($Q$34:$Q$36) -> 658 | AI5: =Table1[[#This Row],[Cluster''s Total Common Services (kWh)]]*Table1[[#This Row],[Percentage of Unit Entitlement (%)]] -> 23.688 | AJ5: =AG5*'Tariff Rates'!$B$3 -> 0 | AK5: =Table1[[#This Row],[Common Services based on Split per Unit Entitlement % to battery (kWh)]]*'Tariff Rates'!$B$3 -> 5.21136 | AL5: =Table1[[#This Row],[Total P2P import (kWh)]]*IF(Table1[[#This Row],[Total Lot Export (kWh)]]=0,'Tariff Rates'!$L$3,'Tariff Rates'!$B$3) -> 9.36 | AM5: =Table1[[#This Row],[P2P Import Consumption over Battery Allowance based on Energy Exceeding Allowance % (kWh)]]*'Tariff Rates'!$J$3 -> 0 | AN5: =Table1[[#This Row],[Energy Import from Grid (kWh)]]*'Tariff Rates'!$E$3 -> 0 | AO5: =SUM(AJ5:AN5) -> 14.57136 | AP5: {=INDEX(Reading_export[1/1/2025],MATCH(1,(Reading_export[Lot]=A5)*(Reading_export[cluster]=$B$1),0))} -> 0 | AQ5: {=INDEX(Reading_export[01/04/2025],MATCH(1,(Reading_export[Lot]=A5)*(Reading_export[cluster]=$B$1),0))} -> 0 | AR5: =Table1[[#This Row],[Last day of reporting period: export]]-Table1[[#This Row],[1st day of reporting period: export]] -> 0 | AS5: =AR5/$AR$38 -> 0 | AT5: =Table1[[#This Row],[Percentage of Total export for Billing Period (%)]]*$AC$38 -> #N/A | AU5: =IF($Y$38-$E$46>0,$Y$38-$E$46,0) -> 835.34 | AV5: =IFERROR(Table1[[#This Row],[Total Cluster Energy Balance for P2P Trading (kWh)2]]*Table1[[#This Row],[Unused Daily Allowance %]],0) -> 51.752713 | AW5: =AS5*AF5 -> 0 | AX5: =Table1[[#This Row],[Cluster''s Total Common Services (kWh)]]*Table1[[#This Row],[Percentage of Total export for Billing Period (%)]] -> 0 | AY5: =$Q$33*Table1[[#This Row],[Percentage of Total export for Billing Period (%)]] -> 0 | AZ5: =Table1[[#This Row],[Total Lot Export (kWh)]]-Table1[[#This Row],[Total Energy Export P2P to battery (kWh)]]-Table1[[#This Row],[Axillary Battery Losses based upon Adjusted % total export (kWh)]]-Table1[[#This Row],[Common Service based upon % total export to battery (kWh)]]-Table1[[#This Row],[EV Charger based upon % total export to battery (kWh)]] -> #N/A | BA5: =IFERROR(IF($AZ$38-$F$46>0,$AZ$38-$F$46,0),0) -> 0 | BB5: =Table1[[#This Row],[Energy Losses When Export to Grid (kWh)]]*Table1[[#This Row],[Percentage of Total export for Billing Period (%)]] -> 0 | BC5: =Table1[[#This Row],[Therotical Energy Export to Grid (kWh)]]-Table1[[#This Row],[Energy Losses When Export to Grid based up % total export (kWh)]] -> #N/A | BD5: =AW5*'Tariff Rates'!$C$3 -> 0 | BE5: =Table1[[#This Row],[Common Service based upon % total export to battery (kWh)]]*'Tariff Rates'!$C$3 -> 0 | BF5: =Table1[[#This Row],[EV Charger based upon % total export to battery (kWh)]]*'Tariff Rates'!$C$3 -> 0 | BG5: =AT5*'Tariff Rates'!$C$3 -> #N/A | BH5: =Table1[[#This Row],[Borrowed Allowance Based on Unused Daily Allowance % (kWh)]]*'Tariff Rates'!$K$3 -> -1.0350543 | BI5: =BC5*'Tariff Rates'!$F$3 -> #N/A | BJ5: =SUM(BD5:BI5) -> #N/A | BK5: =$D$52*Table1[[#This Row],[Percentage of Unit Entitlement (%)]] -> 0 | BL5: =BK5*'Tariff Rates'!$H$3 -> 0 | BM5: =($Q$33)*Table1[[#This Row],[Percentage of Unit Entitlement (%)]]*'Tariff Rates'!$B$3 -> 20.88504 | BN5: =SUM(BM5,BL5) -> 20.88504 | BO5: =BK5 -> 0 | BP5: =BO5+BN5 -> 20.88504 | BQ5: =AO5+BJ5+N5+BP5 -> #N/A | BT5: 1
A6: 2 | B6: {=INDEX(Table_Household_Alloc[Owner],MATCH(1,(Table_Household_Alloc[Lot]=A6)*(Table_Household_Alloc[cluster]=$B$1),0))} -> Margareta Roeck | C6: {=INDEX(Reading_import[Meter'#],MATCH(1,(Table_Household_Alloc[Lot]=A6)*(Table_Household_Alloc[cluster]=$B$1),0))} -> 50002862 | D6: {=INDEX(Table_Household_Alloc[UE % over Cluster],MATCH(1,(Table_Household_Alloc[Lot]=A6)*(Table_Household_Alloc[cluster]=$B$1),0))} -> 0.036 | E6: {=INDEX(Table_Household_Alloc[Stage of Dev.],MATCH(1,(Table_Household_Alloc[Lot]=A6)*(Table_Household_Alloc[cluster]=$B$1),0))} -> UC | F6: {=INDEX(Amanda_energy[Daily_Supply_incl_GST],MATCH(1,(Amanda_energy[Cluster]=$B$1)*(Amanda_energy[Month]=$F$2),0))/MAX($A:$A)} -> 6.3148148 | G6: {=INDEX(Amanda_energy[Daily_Supply_incl_GST],MATCH(1,(Amanda_energy[Cluster]=$B$1)*(Amanda_energy[Month]=$G$2),0))/MAX($A:$A)} -> 5.7037037 | H6: {=INDEX(Amanda_energy[Daily_Supply_incl_GST],MATCH(1,(Amanda_energy[Cluster]=$B$1)*(Amanda_energy[Month]=$H$2),0))/MAX($A:$A)} -> 6.3148148 | I6: =$J$46/MAX($A:$A) -> 1.6722222 | L6: =$L$3*'Tariff Rates'!$D$8*IF(Table1[[#This Row],[Stage of Dev.]]="V",0,1) -> 19.8 | M6: 1.1 | N6: =SUM(F6:M6) -> 40.905556 | O6: {=INDEX(Reading_import[1/1/2025],MATCH(1,(Reading_import[Lot]=A6)*(Reading_import[cluster]=$B$1),0))} -> 252 | P6: {=INDEX(Reading_import[01/04/2025],MATCH(1,(Reading_import[Lot]=A6)*(Reading_import[cluster]=$B$1),0))} -> 342 | Q6: =Table1[[#This Row],[Last day of reporting period: import]]-Table1[[#This Row],[1st day of reporting period: import]] -> 90 | R6: =Q6/$N$3 -> 1 | S6: =Q6/$Q$38 -> 0.010031208 | T6: =IF(Table1[[#This Row],[Stage of Dev.]]="V",0,233*Table1[[#This Row],[Percentage of Unit Entitlement (%)]]) -> 8.388 | U6: =IF(T6>R6,R6,T6) -> 1 | V6: =Table1[[#This Row],[Daily Battery allowance based on UE% (kWh)]]-Table1[[#This Row],[Applicable Battery Allowance Daily Consumption (kWh)]] -> 7.388 | W6: =Table1[[#This Row],[Unused Daily Allowance (kWh)]]/$V$38 -> 0.056514433 | X6: =IF(Table1[[#This Row],[Applicable Battery Allowance Daily Consumption (kWh)]]>Table1[[#This Row],[Total Daily Average Consumptio for Billing Period (kWh)]],Table1[[#This Row],[Total Consumption Import (kWh)]],U6*$N$3) -> 90 | Y6: =IF(Table1[[#This Row],[Applicable Battery Allowance Daily Consumption (kWh)]]>0,ABS(Q6-X6),0) -> 0 | Z6: =IFERROR(Table1[[#This Row],[Energy Exceeding Battery Allowance (kWh)]]/$Y$38,0) -> 0 | AA6: =IF($Y$38-$E$46>0,$Y$38-$E$46,0) -> 835.34 | AB6: =IFERROR(Table1[[#This Row],[Total Cluster Energy Balance for P2P Trading (kWh)]]*Table1[[#This Row],[Energy Exceeding Battery Allowance %]],0) -> 0 | AC6: =Table1[[#This Row],[P2P Import Consumption within Battery Allowance(kWh)]]+Table1[[#This Row],[P2P Import Consumption over Battery Allowance based on Energy Exceeding Allowance % (kWh)]] -> 90 | AD6: =Table1[[#This Row],[Total Consumption Import (kWh)]]-Table1[[#This Row],[Total P2P import (kWh)]] -> 0 | AE6: =IFERROR(Table1[[#This Row],[Total P2P import (kWh)]]/$AC$38,0) -> 0 | AF6: =($Q$32-$AR$32) -> 2476 | AG6: =AF6*AE6 -> 0 | AH6: =SUM($Q$34:$Q$36) -> 658 | AI6: =Table1[[#This Row],[Cluster''s Total Common Services (kWh)]]*Table1[[#This Row],[Percentage of Unit Entitlement (%)]] -> 23.688 | AJ6: =AG6*'Tariff Rates'!$B$3 -> 0 | AK6: =Table1[[#This Row],[Common Services based on Split per Unit Entitlement % to battery (kWh)]]*'Tariff Rates'!$B$3 -> 5.21136 | AL6: =Table1[[#This Row],[Total P2P import (kWh)]]*IF(Table1[[#This Row],[Total Lot Export (kWh)]]=0,'Tariff Rates'!$L$3,'Tariff Rates'!$B$3) -> 32.4 | AM6: =Table1[[#This Row],[P2P Import Consumption over Battery Allowance based on Energy Exceeding Allowance % (kWh)]]*'Tariff Rates'!$J$3 -> 0 | AN6: =Table1[[#This Row],[Energy Import from Grid (kWh)]]*'Tariff Rates'!$E$3 -> 0 | AO6: =SUM(AJ6:AN6) -> 37.61136 | AP6: {=INDEX(Reading_export[1/1/2025],MATCH(1,(Reading_export[Lot]=A6)*(Reading_export[cluster]=$B$1),0))} -> 0 | AQ6: {=INDEX(Reading_export[01/04/2025],MATCH(1,(Reading_export[Lot]=A6)*(Reading_export[cluster]=$B$1),0))} -> 0 | AR6: =Table1[[#This Row],[Last day of reporting period: export]]-Table1[[#This Row],[1st day of reporting period: export]] -> 0 | AS6: =AR6/$AR$38 -> 0 | AT6: =Table1[[#This Row],[Percentage of Total export for Billing Period (%)]]*$AC$38 -> #N/A | AU6: =IF($Y$38-$E$46>0,$Y$38-$E$46,0) -> 835.34 | AV6: =IFERROR(Table1[[#This Row],[Total Cluster Energy Balance for P2P Trading (kWh)2]]*Table1[[#This Row],[Unused Daily Allowance %]],0) -> 47.208767 | AW6: =AS6*AF6 -> 0 | AX6: =Table1[[#This Row],[Cluster''s Total Common Services (kWh)]]*Table1[[#This Row],[Percentage of Total export for Billing Period (%)]] -> 0 | AY6: =$Q$33*Table1[[#This Row],[Percentage of Total export for Billing Period (%)]] -> 0 | AZ6: =Table1[[#This Row],[Total Lot Export (kWh)]]-Table1[[#This Row],[Total Energy Export P2P to battery (kWh)]]-Table1[[#This Row],[Axillary Battery Losses based upon Adjusted % total export (kWh)]]-Table1[[#This Row],[Common Service based upon % total export to battery (kWh)]]-Table1[[#This Row],[EV Charger based upon % total export to battery (kWh)]] -> #N/A | BA6: =IFERROR(IF($AZ$38-$F$46>0,$AZ$38-$F$46,0),0) -> 0 | BB6: =Table1[[#This Row],[Energy Losses When Export to Grid (kWh)]]*Table1[[#This Row],[Percentage of Total export for Billing Period (%)]] -> 0 | BC6: =Table1[[#This Row],[Therotical Energy Export to Grid (kWh)]]-Table1[[#This Row],[Energy Losses When Export to Grid based up % total export (kWh)]] -> #N/A | BD6: =AW6*'Tariff Rates'!$C$3 -> 0 | BE6: =Table1[[#This Row],[Common Service based upon % total export to battery (kWh)]]*'Tariff Rates'!$C$3 -> 0 | BF6: =Table1[[#This Row],[EV Charger based upon % total export to battery (kWh)]]*'Tariff Rates'!$C$3 -> 0 | BG6: =AT6*'Tariff Rates'!$C$3 -> #N/A | BH6: =Table1[[#This Row],[Borrowed Allowance Based on Unused Daily Allowance % (kWh)]]*'Tariff Rates'!$K$3 -> -0.94417533 | BI6: =BC6*'Tariff Rates'!$F$3 -> #N/A | BJ6: =SUM(BD6:BI6) -> #N/A | BK6: =$D$52*Table1[[#This Row],[Percentage of Unit Entitlement (%)]] -> 0 | BL6: =BK6*'Tariff Rates'!$H$3 -> 0 | BM6: =($Q$33)*Table1[[#This Row],[Percentage of Unit Entitlement (%)]]*'Tariff Rates'!$B$3 -> 20.88504 | BN6: =SUM(BM6,BL6) -> 20.88504 | BO6: =BK6 -> 0 | BP6: =BO6+BN6 -> 20.88504 | BQ6: =AO6+BJ6+N6+BP6 -> #N/A | BT6: 2
A7: 3 | B7: {=INDEX(Table_Household_Alloc[Owner],MATCH(1,(Table_Household_Alloc[Lot]=A7)*(Table_Household_Alloc[cluster]=$B$1),0))} -> Alexander Hughes | C7: {=INDEX(Reading_import[Meter'#],MATCH(1,(Table_Household_Alloc[Lot]=A7)*(Table_Household_Alloc[cluster]=$B$1),0))} -> 50002872 | D7: {=INDEX(Table_Household_Alloc[UE % over Cluster],MATCH(1,(Table_Household_Alloc[Lot]=A7)*(Table_Household_Alloc[cluster]=$B$1),0))} -> 0.037 | E7: {=INDEX(Table_Household_Alloc[Stage of Dev.],MATCH(1,(Table_Household_Alloc[Lot]=A7)*(Table_Household_Alloc[cluster]=$B$1),0))} -> O | F7: {=INDEX(Amanda_energy[Daily_Supply_incl_GST],MATCH(1,(Amanda_energy[Cluster]=$B$1)*(Amanda_energy[Month]=$F$2),0))/MAX($A:$A)} -> 6.3148148 | G7: {=INDEX(Amanda_energy[Daily_Supply_incl_GST],MATCH(1,(Amanda_energy[Cluster]=$B$1)*(Amanda_energy[Month]=$G$2),0))/MAX($A:$A)} -> 5.7037037 | H7: {=INDEX(Amanda_energy[Daily_Supply_incl_GST],MATCH(1,(Amanda_energy[Cluster]=$B$1)*(Amanda_energy[Month]=$H$2),0))/MAX($A:$A)} -> 6.3148148 | I7: =$J$46/MAX($A:$A) -> 1.6722222 | L7: =$L$3*'Tariff Rates'!$D$8*IF(Table1[[#This Row],[Stage of Dev.]]="V",0,1) -> 19.8 | M7: 1.1 | N7: =SUM(F7:M7) -> 40.905556 | O7: {=INDEX(Reading_import[1/1/2025],MATCH(1,(Reading_import[Lot]=A7)*(Reading_import[cluster]=$B$1),0))} -> 8271 | P7: {=INDEX(Reading_import[01/04/2025],MATCH(1,(Reading_import[Lot]=A7)*(Reading_import[cluster]=$B$1),0))} -> 9141 | Q7: =Table1[[#This Row],[Last day of reporting period: import]]-Table1[[#This Row],[1st day of reporting period: import]] -> 870 | R7: =Q7/$N$3 -> 9.6666667 | S7: =Q7/$Q$38 -> 0.096968346 | T7: =IF(Table1[[#This Row],[Stage of Dev.]]="V",0,233*Table1[[#This Row],[Percentage of Unit Entitlement (%)]]) -> 8.621 | U7: =IF(T7>R7,R7,T7) -> 8.621 | V7: =Table1[[#This Row],[Daily Battery allowance based on UE% (kWh)]]-Table1[[#This Row],[Applicable Battery Allowance Daily Consumption (kWh)]] -> 0 | W7: =Table1[[#This Row],[Unused Daily Allowance (kWh)]]/$V$38 -> 0 | X7: =IF(Table1[[#This Row],[Applicable Battery Allowance Daily Consumption (kWh)]]>Table1[[#This Row],[Total Daily Average Consumptio for Billing Period (kWh)]],Table1[[#This Row],[Total Consumption Import (kWh)]],U7*$N$3) -> 775.89 | Y7: =IF(Table1[[#This Row],[Applicable Battery Allowance Daily Consumption (kWh)]]>0,ABS(Q7-X7),0) -> 94.11 | Z7: =IFERROR(Table1[[#This Row],[Energy Exceeding Battery Allowance (kWh)]]/$Y$38,0) -> 0.10220017 | AA7: =IF($Y$38-$E$46>0,$Y$38-$E$46,0) -> 835.34 | AB7: =IFERROR(Table1[[#This Row],[Total Cluster Energy Balance for P2P Trading (kWh)]]*Table1[[#This Row],[Energy Exceeding Battery Allowance %]],0) -> 85.371886 | AC7: =Table1[[#This Row],[P2P Import Consumption within Battery Allowance(kWh)]]+Table1[[#This Row],[P2P Import Consumption over Battery Allowance based on Energy Exceeding Allowance % (kWh)]] -> 861.26189 | AD7: =Table1[[#This Row],[Total Consumption Import (kWh)]]-Table1[[#This Row],[Total P2P import (kWh)]] -> 8.7381141 | AE7: =IFERROR(Table1[[#This Row],[Total P2P import (kWh)]]/$AC$38,0) -> 0 | AF7: =($Q$32-$AR$32) -> 2476 | AG7: =AF7*AE7 -> 0 | AH7: =SUM($Q$34:$Q$36) -> 658 | AI7: =Table1[[#This Row],[Cluster''s Total Common Services (kWh)]]*Table1[[#This Row],[Percentage of Unit Entitlement (%)]] -> 24.346 | AJ7: =AG7*'Tariff Rates'!$B$3 -> 0 | AK7: =Table1[[#This Row],[Common Services based on Split per Unit Entitlement % to battery (kWh)]]*'Tariff Rates'!$B$3 -> 5.35612 | AL7: =Table1[[#This Row],[Total P2P import (kWh)]]*IF(Table1[[#This Row],[Total Lot Export (kWh)]]=0,'Tariff Rates'!$L$3,'Tariff Rates'!$B$3) -> 310.05428 | AM7: =Table1[[#This Row],[P2P Import Consumption over Battery Allowance based on Energy Exceeding Allowance % (kWh)]]*'Tariff Rates'!$J$3 -> 1.7074377 | AN7: =Table1[[#This Row],[Energy Import from Grid (kWh)]]*'Tariff Rates'!$E$3 -> 2.6214342 | AO7: =SUM(AJ7:AN7) -> 319.73927 | AP7: {=INDEX(Reading_export[1/1/2025],MATCH(1,(Reading_export[Lot]=A7)*(Reading_export[cluster]=$B$1),0))} -> 0 | AQ7: {=INDEX(Reading_export[01/04/2025],MATCH(1,(Reading_export[Lot]=A7)*(Reading_export[cluster]=$B$1),0))} -> 0 | AR7: =Table1[[#This Row],[Last day of reporting period: export]]-Table1[[#This Row],[1st day of reporting period: export]] -> 0 | AS7: =AR7/$AR$38 -> 0 | AT7: =Table1[[#This Row],[Percentage of Total export for Billing Period (%)]]*$AC$38 -> #N/A | AU7: =IF($Y$38-$E$46>0,$Y$38-$E$46,0) -> 835.34 | AV7: =IFERROR(Table1[[#This Row],[Total Cluster Energy Balance for P2P Trading (kWh)2]]*Table1[[#This Row],[Unused Daily Allowance %]],0) -> 0 | AW7: =AS7*AF7 -> 0 | AX7: =Table1[[#This Row],[Cluster''s Total Common Services (kWh)]]*Table1[[#This Row],[Percentage of Total export for Billing Period (%)]] -> 0 | AY7: =$Q$33*Table1[[#This Row],[Percentage of Total export for Billing Period (%)]] -> 0 | AZ7: =Table1[[#This Row],[Total Lot Export (kWh)]]-Table1[[#This Row],[Total Energy Export P2P to battery (kWh)]]-Table1[[#This Row],[Axillary Battery Losses based upon Adjusted % total export (kWh)]]-Table1[[#This Row],[Common Service based upon % total export to battery (kWh)]]-Table1[[#This Row],[EV Charger based upon % total export to battery (kWh)]] -> #N/A | BA7: =IFERROR(IF($AZ$38-$F$46>0,$AZ$38-$F$46,0),0) -> 0 | BB7: =Table1[[#This Row],[Energy Losses When Export to Grid (kWh)]]*Table1[[#This Row],[Percentage of Total export for Billing Period (%)]] -> 0 | BC7: =Table1[[#This Row],[Therotical Energy Export to Grid (kWh)]]-Table1[[#This Row],[Energy Losses When Export to Grid based up % total export (kWh)]] -> #N/A | BD7: =AW7*'Tariff Rates'!$C$3 -> 0 | BE7: =Table1[[#This Row],[Common Service based upon % total export to battery (kWh)]]*'Tariff Rates'!$C$3 -> 0 | BF7: =Table1[[#This Row],[EV Charger based upon % total export to battery (kWh)]]*'Tariff Rates'!$C$3 -> 0 | BG7: =AT7*'Tariff Rates'!$C$3 -> #N/A | BH7: =Table1[[#This Row],[Borrowed Allowance Based on Unused Daily Allowance % (kWh)]]*'Tariff Rates'!$K$3 -> 0 | BI7: =BC7*'Tariff Rates'!$F$3 -> #N/A | BJ7: =SUM(BD7:BI7) -> #N/A | BK7: =$D$52*Table1[[#This Row],[Percentage of Unit Entitlement (%)]] -> 0 | BL7: =BK7*'Tariff Rates'!$H$3 -> 0 | BM7: =($Q$33)*Table1[[#This Row],[Percentage of Unit Entitlement (%)]]*'Tariff Rates'!$B$3 -> 21.46518 | BN7: =SUM(BM7,BL7) -> 21.46518 | BO7: =BK7 -> 0 | BP7: =BO7+BN7 -> 21.46518 | BQ7: =AO7+BJ7+N7+BP7 -> #N/A | BT7: 3
